<?xml version="1.0"?>
<robot name="diffbot">

  <!-- 색상 정의 -->
  <material name="grey"> <color rgba="0.5 0.5 0.5 1.0"/> </material>
  <material name="black"> <color rgba="0.0 0.0 0.0 1.0"/> </material>

  <!-- ================= BASE ================= -->
  <!-- SDF의 base_link pose (0 0 0.07) 반영 -->
  <link name="base_link">
    <visual>
      <origin xyz="0 0 0.07" rpy="0 0 0"/>
      <geometry> <box size="0.3 0.2 0.1"/> </geometry>
      <material name="grey"/>
    </visual>
  </link>

  <!-- ================= LEFT WHEEL ================= -->
  <!-- SDF pose(0.1 0.1 0.05) 반영 -->
  <link name="left_wheel_link">
    <visual>
      <origin xyz="0 0 0" rpy="1.5708 0 0"/>
      <geometry> <cylinder radius="0.05" length="0.02"/> </geometry>
      <material name="black"/>
    </visual>
  </link>

  <joint name="left_wheel_joint" type="continuous">
    <parent link="base_link"/>
    <child link="left_wheel_link"/>
    <origin xyz="0.1 0.1 0.05" rpy="0 0 0"/>
    <axis xyz="0 1 0"/>
  </joint>

  <!-- ================= RIGHT WHEEL ================= -->
  <!-- SDF pose(0.1 -0.1 0.05) 반영 -->
  <link name="right_wheel_link">
    <visual>
      <origin xyz="0 0 0" rpy="1.5708 0 0"/>
      <geometry> <cylinder radius="0.05" length="0.02"/> </geometry>
      <material name="black"/>
    </visual>
  </link>

  <joint name="right_wheel_joint" type="continuous">
    <parent link="base_link"/>
    <child link="right_wheel_link"/>
    <origin xyz="0.1 -0.1 0.05" rpy="0 0 0"/>
    <axis xyz="0 1 0"/>
  </joint>

  <!-- ================= CASTER (BACK SUPPORT) ================= -->
  <!-- SDF pose(-0.15 0 0.015) 반영 -->
  <link name="caster_link">
    <visual>
      <geometry> <sphere radius="0.025"/> </geometry>
      <material name="black"/>
    </visual>
  </link>

  <joint name="caster_joint" type="fixed">
    <parent link="base_link"/>
    <child link="caster_link"/>
    <origin xyz="-0.15 0 0.015" rpy="0 0 0"/>
  </joint>

  <!-- ================= CAMERA (FRONT TOP) ================= -->
  <!-- SDF pose(0.15 0 0.12) 반영 -->
  <link name="camera_link">
    <visual>
      <geometry> <box size="0.02 0.05 0.02"/> </geometry>
      <material name="black"/>
    </visual>
  </link>

  <joint name="camera_joint" type="fixed">
    <parent link="base_link"/>
    <child link="camera_link"/>
    <origin xyz="0.15 0 0.12" rpy="0 0 0"/>
  </joint>
  <!-- ================= LIDAR (Top Center) ================= -->
  <link name="base_scan">
    <visual>
      <!-- 올바른 URDF 형식: 속성(Attribute) 사용 -->
      <geometry> <cylinder radius="0.02" length="0.04"/> </geometry> 
      <material name="black"/>
    </visual>
  </link>

  <joint name="lidar_joint" type="fixed">
    <parent link="base_link"/>
    <child link="base_scan"/>
    <!-- SDF의 pose (0 0 0.17) 반영 -->
    <origin xyz="0 0 0.17" rpy="0 0 0"/>
  </joint>
</robot>