<?xml version="1.0"?>
<robot name="diffbot">

  <material name="grey"> <color rgba="0.5 0.5 0.5 1.0"/> </material>
  <material name="black"> <color rgba="0.0 0.0 0.0 1.0"/> </material>

  <link name="base_link">
    <visual>
      <origin xyz="0 0 0.05" rpy="0 0 0"/>
      <geometry> <box size="0.2 0.1 0.05"/> </geometry>
      <material name="grey"/>
    </visual>
  </link>

  <link name="left_wheel_link">
    <visual>
      <origin xyz="0 0 0" rpy="1.5708 0 0"/>
      <geometry> <cylinder radius="0.025" length="0.02"/> </geometry>
      <material name="black"/>
    </visual>
  </link>

  <joint name="left_wheel_joint" type="continuous">
    <parent link="base_link"/>
    <child link="left_wheel_link"/>
    <origin xyz="0.05 0.06 0.025" rpy="0 0 0"/>
    <axis xyz="0 1 0"/>
  </joint>

  <link name="right_wheel_link">
    <visual>
      <origin xyz="0 0 0" rpy="1.5708 0 0"/>
      <geometry> <cylinder radius="0.025" length="0.02"/> </geometry>
      <material name="black"/>
    </visual>
  </link>

  <joint name="right_wheel_joint" type="continuous">
    <parent link="base_link"/>
    <child link="right_wheel_link"/>
    <origin xyz="0.05 -0.06 0.025" rpy="0 0 0"/>
    <axis xyz="0 1 0"/>
  </joint>

  <link name="caster_link">
    <visual>
      <geometry> <sphere radius="0.025"/> </geometry>
      <material name="black"/>
    </visual>
  </link>

  <joint name="caster_joint" type="fixed">
    <parent link="base_link"/>
    <child link="caster_link"/>
    <origin xyz="-0.08 0 0.025" rpy="0 0 0"/>
  </joint>

  <link name="camera_link">
    <visual>
      <origin xyz="0 0 0" rpy="0 0 0"/>
      <geometry> <box size="0.02 0.05 0.02"/> </geometry>
      <material name="black"/>
    </visual>
  </link>

  <joint name="camera_joint" type="fixed">
    <parent link="base_link"/>
    <child link="camera_link"/>
    <origin xyz="0.1 0 0.08" rpy="0 0 0"/>
  </joint>

  <link name="base_scan">
    <visual>
      <origin xyz="0 0 0" rpy="0 0 0"/>
      <geometry> <cylinder radius="0.02" length="0.04"/> </geometry> 
      <material name="black"/>
    </visual>
  </link>

  <joint name="lidar_joint" type="fixed">
    <parent link="base_link"/>
    <child link="base_scan"/>
    <origin xyz="0 0 0.1" rpy="0 0 0"/>
  </joint>

</robot>