<?xml version="1.0" ?>
<sdf version="1.6">
  <model name="diffbot">
    <static>false</static>

    <link name="base_link">
      <pose>0 0 0.05 0 0 0</pose>
      <inertial>
        <mass>2.0</mass>
        <inertia>
          <ixx>0.01</ixx><iyy>0.01</iyy><izz>0.01</izz>
        </inertia>
      </inertial>
      <collision name="base_collision">
        <geometry><box><size>0.2 0.1 0.05</size></box></geometry>
      </collision>
      <visual name="base_visual">
        <geometry><box><size>0.2 0.1 0.05</size></box></geometry>
      </visual>
    </link>

    <link name="left_wheel_link">
      <pose>0.05 0.06 0.025 0 0 0</pose>
      <inertial>
        <mass>0.2</mass>
        <inertia><ixx>0.001</ixx><iyy>0.001</iyy><izz>0.001</izz></inertia>
      </inertial>
      <collision name="left_wheel_collision">
        <pose>0 0 0 1.5708 0 0</pose>
        <geometry><cylinder><radius>0.025</radius><length>0.02</length></cylinder></geometry>
      </collision>
      <visual name="left_wheel_visual">
        <pose>0 0 0 1.5708 0 0</pose>
        <geometry><cylinder><radius>0.025</radius><length>0.02</length></cylinder></geometry>
      </visual>
    </link>

    <joint name="left_wheel_joint" type="revolute">
      <parent>base_link</parent>
      <child>left_wheel_link</child>
      <axis>
        <xyz>0 1 0</xyz>
        <limit><effort>5</effort><velocity>10</velocity></limit>
        <dynamics><damping>0.1</damping><friction>0.05</friction></dynamics>
      </axis>
    </joint>

    <link name="right_wheel_link">
      <pose>0.05 -0.06 0.025 0 0 0</pose>
      <inertial>
        <mass>0.2</mass>
        <inertia><ixx>0.001</ixx><iyy>0.001</iyy><izz>0.001</izz></inertia>
      </inertial>
      <collision name="right_wheel_collision">
        <pose>0 0 0 1.5708 0 0</pose>
        <geometry><cylinder><radius>0.025</radius><length>0.02</length></cylinder></geometry>
      </collision>
      <visual name="right_wheel_visual">
        <pose>0 0 0 1.5708 0 0</pose>
        <geometry><cylinder><radius>0.025</radius><length>0.02</length></cylinder></geometry>
      </visual>
    </link>

    <joint name="right_wheel_joint" type="revolute">
      <parent>base_link</parent>
      <child>right_wheel_link</child>
      <axis>
        <xyz>0 1 0</xyz>
        <limit><effort>5</effort><velocity>10</velocity></limit>
        <dynamics><damping>0.1</damping><friction>0.05</friction></dynamics>
      </axis>
    </joint>

    <link name="caster_link">
      <pose>-0.08 0 0.025 0 0 0</pose>
      <inertial>
        <mass>0.1</mass>
        <inertia><ixx>0.0001</ixx><iyy>0.0001</iyy><izz>0.0001</izz></inertia>
      </inertial>
      <collision name="caster_collision">
        <geometry><sphere><radius>0.025</radius></sphere></geometry>
        <surface><friction><ode><mu>0.01</mu><mu2>0.01</mu2></ode></friction></surface>
      </collision>
      <visual name="caster_visual">
        <geometry><sphere><radius>0.025</radius></sphere></geometry>
      </visual>
    </link>

    <joint name="caster_joint" type="fixed">
      <parent>base_link</parent>
      <child>caster_link</child>
    </joint>

    <link name="camera_link">
      <pose>0.1 0 0.08 0 0 0</pose> 
      <visual name="camera_visual">
        <geometry><box><size>0.02 0.05 0.02</size></box></geometry>
        <material><ambient>0 0 0 1</ambient><diffuse>0 0 0 1</diffuse></material>
      </visual>
      <sensor name="camera" type="camera">
        <update_rate>30.0</update_rate>
        <visualize>true</visualize>
        <camera name="head">
          <horizontal_fov>1.39626</horizontal_fov>
          <image><width>800</width><height>600</height><format>R8G8B8</format></image>
          <clip><near>0.02</near><far>300</far></clip>
        </camera>
        <plugin name="camera_controller" filename="libgazebo_ros_camera.so">
          <ros><remapping>image_raw:=camera/image_raw</remapping></ros>
          <frame_name>camera_link</frame_name>
        </plugin>
      </sensor>
    </link>

    <joint name="camera_joint" type="fixed">
      <parent>base_link</parent>
      <child>camera_link</child>
    </joint>

    <link name="base_scan">
      <pose>0 0 0.1 0 0 0</pose> 
      <visual name="lidar_visual">
        <geometry><cylinder><radius>0.02</radius><length>0.04</length></cylinder></geometry>
        <material><ambient>0.1 0.1 0.1 1</ambient><diffuse>0.1 0.1 0.1 1</diffuse></material>
      </visual>
      <sensor name="lidar" type="ray">
        <always_on>true</always_on>
        <update_rate>10.0</update_rate>
        <visualize>true</visualize>
        <ray>
          <scan><horizontal><samples>360</samples><min_angle>-3.14159</min_angle><max_angle>3.14159</max_angle></horizontal></scan>
          <range><min>0.12</min><max>10.0</max></range> </ray>
        <plugin name="lidar_controller" filename="libgazebo_ros_ray_sensor.so">
          <ros><remapping>~/out:=scan</remapping></ros>
          <output_type>sensor_msgs/LaserScan</output_type>
          <frame_name>base_scan</frame_name>
        </plugin>
      </sensor>
    </link>

    <joint name="lidar_joint" type="fixed">
      <parent>base_link</parent>
      <child>base_scan</child>
    </joint>

    <plugin name="diff_drive" filename="libgazebo_ros_diff_drive.so">
      <left_joint>left_wheel_joint</left_joint>
      <right_joint>right_wheel_joint</right_joint>
      <wheel_separation>0.12</wheel_separation>
      <wheel_diameter>0.05</wheel_diameter>
      <max_wheel_torque>5</max_wheel_torque> 
      <max_wheel_acceleration>1.0</max_wheel_acceleration>
      <command_topic>cmd_vel</command_topic>
      <odometry_topic>odom</odometry_topic>
      <odometry_frame>odom</odometry_frame>
      <robot_base_frame>base_link</robot_base_frame>
      <publish_odom>true</publish_odom>
      <publish_odom_tf>true</publish_odom_tf>
      <publish_wheel_tf>true</publish_wheel_tf>
    </plugin>
  </model>
</sdf>